Workbook

Sheet Runtimes_SPARQL1.0
B1: Total Query Execution Time (msec)
A3: Query | B3: FedX(cold) | C3: FedX(100% cached) | D3: SPLENDID | E3: ANAPSID | F3: FedX+HiBISCuS | G3: SPLENDID+HiBISCuS
A4: S1 | B4: 430 | C4: 248 | D4: 996 | E4: 278 | F4: 240 | G4: 270 | I4: 227 | J4: =E4-'source selection'!O8 -> 51
A5: S2 | B5: 330 | C5: 192 | D5: 395 | E5: 80 | F5: 199 | G5: 169 | I5: 46 | J5: =E5-'source selection'!O9 -> 34
A6: S3 | B6: 500 | C6: 255 | D6: 695 | E6: 116 | F6: 180 | G6: 503 | I6: 70 | J6: =E6-'source selection'!O10 -> 46
A7: S4 | B7: 540 | C7: 270 | D7: 509 | E7: 118 | F7: 300 | G7: 313 | I7: 74 | J7: =E7-'source selection'!O11 -> 44
A8: S5 | B8: 478 | C8: 233 | D8: 648 | E8: 349 | F8: 229 | G8: 340 | I8: 65 | J8: =E8-'source selection'!O12 -> 284
A9: S6 | B9: 1840 | C9: 1789 | D9: 70131 | E9: 308514 | F9: 1790 | G9: 36035 | I9: 197 | J9: =E9-'source selection'!O13 -> 308317
A10: S7 | B10: 948 | C10: 745 | D10: 8246 | E10: 298954 | F10: 700 | G10: 8221 | I10: 273 | J10: =E10-'source selection'!O14 -> 298681
A11: S8 | B11: 650 | C11: 393 | D11: 494 | E11: 454 | F11: 398 | G11: 310 | I11: 51 | J11: =E11-'source selection'!O15 -> 403
A12: S9 | B12: 672 | C12: 490 | D12: 2640 | E12: 1024 | F12: 429 | G12: 1530 | I12: 356 | J12: =E12-'source selection'!O16 -> 668
A13: S10 | B13: 9585 | C13: 9210 | D13: 17868 | E13: 18949 | F13: 9288 | G13: 15130 | I13: 262 | J13: =E13-'source selection'!O17 -> 18687
A14: S11 | B14: 343 | C14: 159 | D14: 461 | E14: 17496 | F14: 165 | G14: 470 | I14: 333 | J14: =E14-'source selection'!O18 -> 17163
A15: S12 | B15: 4966 | C15: 4711 | D15: 112396 | E15: 5151 | F15: 4611 | G15: 97110 | I15: 105 | J15: =E15-'source selection'!O19 -> 5046
... A17: S14 | B17: 12830 | C17: 12727 | D17: 861731 | E17: 3870 | F17: 12745 | G17: 751211 | I17: 81 | J17: =E17-'source selection'!O21 -> 3789
A18: Avg. | B18: =AVERAGE(B4:B17) -> 4596.0714 | C18: =AVERAGE(C4:C17) -> 4400.8571 | D18: =AVERAGE(D4:D17) -> 77414 | E18: =AVERAGE(E4:E17) -> 47228.429 | F18: =AVERAGE(F4:F17) -> 4383.8571 | G18: =AVERAGE(G4:G17) -> 65530.857
A20: Query | B20: FedX(cold) | C20: FedX(100% cached) | D20: SPLENDID | E20: ANAPSID | F20: FedX+HiBISCuS | G20: SPLENDID+HiBISCuS
A21: C1 | B21: RE | C21: RE | D21: 71415 | E21: 10318 | F21: RE | G21: 65420
A22: C2 | B22: 4391 | C22: 4106 | D22: 98212 | E22: RE | F22: 4000 | G22: 77121
A23: C3 | B23: 28416 | C23: 28370 | D23: 240171 | E23: TO | F23: 23703 | G23: 126284
A24: C4 | B24: 922368 | C24: 922276 | D24: RE | E24: 145615 | F24: 902131 | G24: RE
A25: C5 | B25: TO | C25: TO | D25: TO (2.2%) | E25: RE | F25: TO | G25: 869922
A26: C6 | B26: 48530 | C26: 48639 | D26: 46276 | E26: 19991 | F26: 40719 | G26: 28276
A27: C7 | B27: 2945 | C27: 2645 | D27: 13517 | E27: 1348 | F27: 2517 | G27: 1860
A28: C8 | B28: 13457 | C28: 13200 | D28: 99691 | E28: 2643 | F28: 11012 | G28: 10825
A29: C9 | B29: TO | C29: TO | D29: RE | E29: 20658 | F29: TO | G29: RE
A30: C10 | B30: 8969 | C30: 8738 | D30: 18680 | E30: 38486 | F30: 8400 | G30: 7319
A31: Avg. | B31: =AVERAGE(B30,B26:B28,B22:B24,B32) -> 428634.5 | C31: =AVERAGE(C30,C28,C27,C26,C24,C23,C22,C32) -> 428496.75 | D31: =AVERAGE(D30,D25:D28,D21:D23) -> 83994.571 | E31: =AVERAGE(E30,E26:E28,E24,E21,E32) -> 374057.29 | F31: =AVEDEV(F30,F22:F24,F32) -> 786734.96 | G31: =AVERAGE(G30,G25:G28,G21:G23) -> 148378.38
B32: 2400000 | C32: 2400000 | E32: 2400000 | F32: 2400000
A33: RE = Runtime Error
A34: TO = Time out of 20 min
A35: NS = Not Supported
A36: Note: 20 min was added while calculating averages for each time out.
A39: Query | B39: FedX(cold) | C39: FedX(100% cached) | D39: SPLENDID | E39: ANAPSID | F39: FedX+HiBISCuS | G39: SPLENDID+HiBISCuS
A40: L1 | B40: TO (7.2 %) | C40: =B40 -> TO (7.2 %) | D40: 123735 (2.73 %) | E40: 19672 (15.76 %) | F40: TO (7.2 %) | G40: 123700 (2.73 %)
A41: L2 | B41: 35 (0 %) | C41: =B41 -> 35 (0 %) | D41: 45473 (1.8 %) | E41: TO (0 %) | F41: 76 (0 %) | G41: 45479 (1.8 %)
A42: L3 | B42: 27 (0 %) | C42: =B42 -> 27 (0 %) | D42: 4877696 | E42: TO (0 %) | F42: 47 (0 %) | G42: 4877991
A43: L4 | B43: TO (0.08 %) | C43: =B43 -> TO (0.08 %) | D43: 7535531 (0%) | E43: 8775598 (0 %) | F43: 62595 (48.34 %) | G43: 7535200 (0%)
A44: L5 | B44: 340 (0 %) | C44: =B44 -> 340 (0 %) | D44: RE (0 %) | E44: TO (0 %) | F44: 330 (0 %) | G44: RE (0 %)
A45: L6 | B45: TO (0 %) | C45: =B45 -> TO (0 %) | D45: RE (0 %) | E45: TO (0 %) | F45: 6127090 (0 %) | G45: RE (0 %)
...

Sheet F1 Scores
F3: The table shows the queries for which at least one of the systems gives incomplete or incorrect results. For other queries all system gives correct and complete results and thus not shown
E5: Query | F5: FedX | I5: SPLENDID | L5: ANAPSID | O5: FedX+HiBISCuS | R5: SPLENDID+HiBISCuS
F6: Precision | G6: Recall | H6: F1 | I6: Precision | J6: Recall | K6: F1 | L6: Precision | M6: Recall | N6: F1 | O6: Precision | P6: Recall | Q6: F1 | R6: Precision | S6: Recall | T6: F1
E7: C5 | F7: TO | G7: TO | H7: TO | I7: 1 | J7: 0.022 | K7: =2*J7*I7/(I7+J7) -> 0.043052838 | L7: TO | M7: TO | N7: TO | O7: TO | P7: TO | Q7: TO | R7: 1 | S7: 1 | T7: =2*S7*R7/(R7+S7) -> 1
E8: C7 | F8: 0.25 | G8: 0.19 | H8: =2*F8*G8/(F8+G8) -> 0.21590909 | I8: 1 | J8: 1 | K8: =2*J8*I8/(I8+J8) -> 1 | L8: 1 | M8: 1 | N8: =2*L8*M8/(L8+M8) -> 1 | O8: 0.25 | P8: 0.19 | Q8: =2*O8*P8/(O8+P8) -> 0.21590909 | R8: 1 | S8: 1 | T8: =2*S8*R8/(R8+S8) -> 1
E9: S14 (v1.1) | F9: 1 | G9: =1054/1620 -> 0.65061728 | H9: =2*F9*G9/(F9+G9) -> 0.78833209 | I9: 1 | J9: 1 | K9: =2*J9*I9/(I9+J9) -> 1 | L9: 1 | M9: 1 | N9: =2*L9*M9/(L9+M9) -> 1 | O9: 1 | P9: =1054/1620 -> 0.65061728 | Q9: =2*O9*P9/(O9+P9) -> 0.78833209 | R9: 1 | S9: 1 | T9: =2*S9*R9/(R9+S9) -> 1
E10: C6 (v1.1) | F10: 1 | G10: =145/148 -> 0.97972973 | H10: =2*F10*G10/(F10+G10) -> 0.98976109 | I10: 1 | J10: 1 | K10: =2*J10*I10/(I10+J10) -> 1 | L10: 1 | M10: 1 | N10: =2*L10*M10/(L10+M10) -> 1 | O10: 1 | P10: =145/148 -> 0.97972973 | Q10: =2*O10*P10/(O10+P10) -> 0.98976109 | R10: 1 | S10: 1 | T10: =2*S10*R10/(R10+S10) -> 1
E11: L1 | F11: TO | G11: TO | H11: TO | I11: 1 | J11: 0.03 | K11: =2*J11*I11/(I11+J11) -> 0.058252427 | L11: 1 | M11: 0.16 | N11: =2*L11*M11/(L11+M11) -> 0.27586207 | O11: TO | P11: TO | Q11: TO | R11: 1 | S11: 0.03 | T11: =2*S11*R11/(R11+S11) -> 0.058252427
E12: L2 | F12: 0 | G12: 0 | H12: 0 | I12: TO | J12: TO | K12: TO | L12: TO | M12: TO | N12: TO | O12: 0 | P12: 0 | Q12: 0 | R12: 1 | S12: 0.02 | T12: =2*S12*R12/(R12+S12) -> 0.039215686
E13: L3 | F13: 0 | G13: 0 | H13: 0 | I13: TO | J13: TO | K13: TO | L13: TO | M13: TO | N13: TO | O13: 0 | P13: 0 | Q13: 0 | R13: 1 | S13: 1 | T13: =2*S13*R13/(R13+S13) -> 1
E14: L4 | F14: TO | G14: TO | H14: TO | I14: 0 | J14: 0 | K14: 0 | L14: 0 | M14: 0 | N14: 0 | O14: 1 | P14: 0.48 | Q14: =2*O14*P14/(O14+P14) -> 0.64864865 | R14: 0 | S14: 0 | T14: 0
E15: L5 | F15: 0 | G15: 0 | H15: 0 | I15: RE | J15: RE | K15: RE | L15: TO | M15: TO | N15: TO | O15: 0 | P15: 0 | Q15: 0 | R15: RE | S15: RE | T15: RE
E16: L6 | F16: TO | G16: TO | H16: TO | I16: RE | J16: RE | K16: RE | L16: TO | M16: TO | N16: TO | O16: 0 | P16: 0 | Q16: 0 | R16: RE | S16: RE | T16: RE

Sheet source selection
E3: Comparision of the source selection of different SPARQL federation engines in terms of : Total number of triple pattern-wise sources selected #TP
E4: Total SPARQL ASK request #AR, Source selection time (cold , i.e, without cache) SSTC, Source selection time (warm, i.e., with cache) SSTW
F6: FedX | J6: SPLENDID | M6: ANAPSID | P6: HiBISCus | T6: Optimal
E7: Query | F7: #TP | G7: #AR | H7: SSTC | I7: SSTW | J7: #TP | K7: #AR | L7: SST | M7: #TP | N7: #AR | O7: SST | P7: #TP | Q7: #AR | R7: SST | S7: SSTW | T7: #TP
E8: S1 | F8: 15 | G8: 39 | H8: 238 | I8: 5 | J8: 15 | K8: 34 | L8: 622 | M8: 3 | N8: 23 | O8: 227 | P8: 4 | Q8: 26 | R8: 322 | S8: 80 | T8: 3 | V8: =F8-P8 -> 11 | W8: =J8-P8 -> 11
E9: S2 | F9: 3 | G9: 39 | H9: 229 | I9: 6 | J9: 3 | K9: 9 | L9: 380 | M9: 3 | N9: 1 | O9: 46 | P9: 3 | Q9: 13 | R9: 201 | S9: 8 | T9: 3 | V9: =F9-P9 -> 0 | W9: =J9-P9 -> 0
E10: S3 | F10: 12 | G10: 65 | H10: 275 | I10: 5 | J10: 12 | K10: 2 | L10: 358 | M10: 5 | N10: 2 | O10: 70 | P10: 5 | Q10: 0 | R10: 52 | S10: 52 | T10: 5 | V10: =F10-P10 -> 7 | W10: =J10-P10 -> 7
E11: S4 | F11: 19 | G11: 65 | H11: 270 | I11: 7 | J11: 19 | K11: 2 | L11: 340 | M11: 5 | N11: 3 | O11: 74 | P11: 5 | Q11: 0 | R11: 130 | S11: 114 | T11: 5 | V11: =F11-P11 -> 14 | W11: =J11-P11 -> 14
E12: S5 | F12: 11 | G12: 52 | H12: 268 | I12: 8 | J12: 11 | K12: 1 | L12: 330 | M12: 4 | N12: 1 | O12: 65 | P12: 4 | Q12: 0 | R12: 90 | S12: 80 | T12: 4 | V12: =F12-P12 -> 7 | W12: =J12-P12 -> 7
E13: S6 | F13: 9 | G13: 52 | H13: 245 | I13: 5 | J13: 9 | K13: 2 | L13: 303 | M13: 9 | N13: 10 | O13: 197 | P13: 8 | Q13: 0 | R13: 96 | S13: 77 | T13: 8 | V13: =F13-P13 -> 1 | W13: =J13-P13 -> 1
E14: S7 | F14: 13 | G14: 52 | H14: 248 | I14: 6 | J14: 13 | K14: 2 | L14: 354 | M14: 6 | N14: 5 | O14: 273 | P14: 6 | Q14: 0 | R14: 149 | S14: 102 | T14: 6 | V14: =F14-P14 -> 7 | W14: =J14-P14 -> 7
E15: S8 | F15: 1 | G15: 26 | H15: 223 | I15: 5 | J15: 1 | K15: 0 | L15: 189 | M15: 1 | N15: 0 | O15: 51 | P15: 1 | Q15: 0 | R15: 9 | S15: 9 | T15: 1 | V15: =F15-P15 -> 0 | W15: =J15-P15 -> 0
E16: S9 | F16: 15 | G16: 39 | H16: 240 | I16: 6 | J16: 15 | K16: 34 | L16: 592 | M16: 15 | N16: 23 | O16: 356 | P16: 9 | Q16: 26 | R16: 449 | S16: 28 | T16: 3 | V16: =F16-P16 -> 6 | W16: =J16-P16 -> 6
E17: S10 | F17: 12 | G17: 65 | H17: 296 | I17: 5 | J17: 12 | K17: 1 | L17: 334 | M17: 5 | N17: 16 | O17: 262 | P17: 5 | Q17: 0 | R17: 250 | S17: 240 | T17: 5 | V17: =F17-P17 -> 7 | W17: =J17-P17 -> 7
E18: S11 | F18: 7 | G18: 91 | H18: 300 | I18: 7 | J18: 7 | K18: 2 | L18: 299 | M18: 7 | N18: 0 | O18: 333 | P18: 7 | Q18: 0 | R18: 12 | S18: 9 | T18: 7 | V18: =F18-P18 -> 0 | W18: =J18-P18 -> 0
E19: S12 | F19: 10 | G19: 78 | H19: 260 | I19: 5 | J19: 10 | K19: 1 | L19: 355 | M19: 7 | N19: 4 | O19: 105 | P19: 8 | Q19: 0 | R19: 115 | S19: 99 | T19: 6 | V19: =F19-P19 -> 2 | W19: =J19-P19 -> 2
... E21: S14 | F21: 6 | G21: 65 | H21: 268 | I21: 5 | J21: 6 | K21: 1 | L21: 252 | M21: 5 | N21: 2 | O21: 81 | P21: 6 | Q21: 0 | R21: 94 | S21: 67 | T21: 6 | V21: =F21-P21 -> 0 | W21: =J21-P21 -> 0
E22: Total/Avg | F22: =SUM(F8:F21) -> 142 | G22: =SUM(G8:G21) -> 793 | H22: =SUM(H8:H21)/14 -> 258.71429 | I22: =SUM(I8:I21)/14 -> 5.5714286 | J22: =SUM(J8:J21) -> 142 | K22: =SUM(K8:K21) -> 93 | L22: =SUM(L8:L21)/14 -> 355 | M22: =SUM(M8:M21) -> 80 | N22: =SUM(N8:N21) -> 114 | O22: =SUM(O8:O21)/14 -> 165.71429 | P22: =SUM(P8:P21) -> 78 | Q22: =SUM(Q8:Q21) -> 65 | R22: =SUM(R8:R21)/14 -> 150.07143 | S22: =SUM(S8:S21)/14 -> 76.928571 | T22: =SUM(T8:T21) -> 67
E23: C1 | F23: 11 | G23: 104 | H23: 308 | I23: 7 | J23: 11 | K23: 1 | L23: 291 | M23: 8 | N23: 1 | O23: 72 | P23: 9 | Q23: 0 | R23: 120 | S23: 114 | T23: 8 | V23: =F23-P23 -> 2 | W23: =J23-P23 -> 2
E24: C2 | F24: 11 | G24: 104 | H24: 307 | I24: 6 | J24: 11 | K24: 1 | L24: 347 | M24: 8 | N24: 2 | O24: 180 | P24: 9 | Q24: 0 | R24: 23 | S24: 16 | T24: 8 | V24: =F24-P24 -> 2 | W24: =J24-P24 -> 2
E25: C3 | F25: 21 | G25: 104 | H25: 318 | I25: 5 | J25: 21 | K25: 3 | L25: 350 | M25: 10 | N25: 33 | O25: 549 | P25: 11 | Q25: 0 | R25: 230 | S25: 200 | T25: 10 | V25: =F25-P25 -> 10 | W25: =J25-P25 -> 10
E26: C4 | F26: 28 | G26: 156 | H26: 360 | I26: 7 | J26: 28 | K26: 0 | L26: 230 | M26: 28 | N26: 32 | O26: 451 | P26: 18 | Q26: 0 | R26: 45 | S26: 45 | T26: 18 | V26: =F26-P26 -> 10 | W26: =J26-P26 -> 10
E27: C5 | F27: 33 | G27: 104 | H27: 315 | I27: 6 | J27: 33 | K27: 0 | L27: 199 | M27: 8 | N27: 3 | O27: 156 | P27: 10 | Q27: 0 | R27: 56 | S27: 55 | T27: 8 | V27: =F27-P27 -> 23 | W27: =J27-P27 -> 23
E28: C6 | F28: 24 | G28: 117 | H28: 430 | I28: 5 | J28: 24 | K28: 0 | L28: 245 | M28: 9 | N28: 3 | O28: 90 | P28: 9 | Q28: 0 | R28: 450 | S28: 445 | T28: 9 | V28: =F28-P28 -> 15 | W28: =J28-P28 -> 15
E29: C7 | F29: 17 | G29: 117 | H29: 436 | I29: 7 | J29: 17 | K29: 2 | L29: 422 | M29: 9 | N29: 5 | O29: 380 | P29: 9 | Q29: 0 | R29: 168 | S29: 175 | T29: 9 | V29: =F29-P29 -> 8 | W29: =J29-P29 -> 8
E30: C8 | F30: 25 | G30: 143 | H30: 402 | I30: 4 | J30: 25 | K30: 2 | L30: 300 | M30: 11 | N30: 2 | O30: 308 | P30: 11 | Q30: 0 | R30: 200 | S30: 187 | T30: 11 | V30: =F30-P30 -> 14 | W30: =J30-P30 -> 14
E31: C9 | F31: 16 | G31: 117 | H31: 400 | I31: 6 | J31: 16 | K31: 2 | L31: 480 | M31: 9 | N31: 16 | O31: 185 | P31: 9 | Q31: 0 | R31: 180 | S31: 170 | T31: 9 | V31: =F31-P31 -> 7 | W31: =J31-P31 -> 7
E32: C10 | F32: 13 | G32: 130 | H32: 350 | I32: 8 | J32: 13 | K32: 0 | L32: 240 | M32: 11 | N32: 6 | O32: 160 | P32: 11 | Q32: 0 | R32: 150 | S32: 140 | T32: 11 | V32: =F32-P32 -> 2 | W32: =J32-P32 -> 2
E33: Total/Avg | F33: =SUM(F23:F32) -> 199 | G33: =SUM(G23:G32) -> 1196 | H33: =AVERAGE(H23:H32) -> 362.6 | I33: =AVERAGE(I23:I32) -> 6.1 | J33: =SUM(J23:J32) -> 199 | K33: =SUM(K23:K32) -> 11 | L33: =AVERAGE(L23:L32) -> 310.4 | M33: =SUM(M23:M32) -> 111 | N33: =SUM(N23:N32) -> 103 | O33: =AVERAGE(O23:O32) -> 253.1 | P33: =SUM(P23:P32) -> 106 | Q33: 0 | R33: =AVERAGE(R23:R32) -> 162.2 | S33: =AVERAGE(S23:S32) -> 154.7 | T33: =SUM(T23:T32) -> 101
E34: B1 | F34: 14 | G34: 78 | H34: 282 | I34: 5 | J34: 14 | K34: 12 | L34: 720 | M34: 6 | N34: 10 | O34: 260 | P34: 14 | Q34: 0 | R34: 124 | S34: 100 | T34: 6 | V34: =F34-P34 -> 0 | W34: =J34-P34 -> 0
E35: B2 | F35: 10 | G35: 78 | H35: 279 | I35: 7 | J35: 10 | K35: 1 | L35: 230 | M35: 6 | N35: 5 | O35: 142 | P35: 10 | Q35: 0 | R35: 94 | S35: 80 | T35: 6 | V35: =F35-P35 -> 0 | W35: =J35-P35 -> 0
E36: B3 | F36: 10 | G36: 91 | H36: 314 | I36: 9 | J36: 10 | K36: 2 | L36: 314 | M36: 7 | N36: 5 | O36: 146 | P36: 11 | Q36: 0 | R36: 99 | S36: 103 | T36: 7 | V36: =F36-P36 -> -1 | W36: =J36-P36 -> -1
E37: B4 | F37: 18 | G37: 104 | H37: 321 | I37: 7 | J37: 18 | K37: 0 | L37: 198 | M37: 8 | N37: 8 | O37: 338 | P37: 16 | Q37: 0 | R37: 80 | S37: 77 | T37: 8 | V37: =F37-P37 -> 2 | W37: =J37-P37 -> 2
E38: B5 | F38: 21 | G38: 143 | H38: 400 | I38: 5 | J38: 21 | K38: 2 | L38: 277 | M38: 12 | N38: 31 | O38: 10255 | P38: 20 | Q38: 0 | R38: 130 | S38: 125 | T38: 11 | V38: =F38-P38 -> 1 | W38: =J38-P38 -> 1
E39: B6 | F39: 20 | G39: 130 | H39: 419 | I39: 4 | J39: 20 | K39: 2 | L39: 298 | M39: 10 | N39: 52 | O39: 13173 | P39: 18 | Q39: 0 | R39: 160 | S39: 160 | T39: 10 | V39: =F39-P39 -> 2 | W39: =J39-P39 -> 2
E40: B7 | F40: 20 | G40: 65 | H40: 320 | I40: 6 | J40: 20 | K40: 13 | L40: 240 | M40: 6 | N40: 7 | O40: 1822 | P40: 9 | Q40: 0 | R40: 270 | S40: 236 | T40: 5 | V40: =F40-P40 -> 11 | W40: =J40-P40 -> 11
E41: B8 | F41: 20 | G41: 104 | H41: 366 | I41: 7 | J41: 20 | K41: 12 | L41: 700 | M41: 9 | N41: 17 | O41: 404 | P41: 20 | Q41: 0 | R41: 170 | S41: 156 | T41: 8 | V41: =F41-P41 -> 0 | W41: =J41-P41 -> 0
E42: Total/Avg | F42: =SUM(F34:F41) -> 133 | G42: =SUM(G34:G41) -> 793 | H42: =SUM(H34:H41)/8 -> 337.625 | I42: =SUM(I34:I41)/8 -> 6.25 | J42: =SUM(J34:J41) -> 133 | K42: =SUM(K34:K41) -> 44 | L42: =SUM(L34:L41)/8 -> 372.125 | M42: =SUM(M34:M41) -> 64 | N42: =SUM(N34:N41) -> 135 | O42: =SUM(O34:O41)/8 -> 3317.5 | P42: =SUM(P34:P41) -> 118 | Q42: =SUM(Q34:Q41) -> 0 | R42: =SUM(R34:R41)/8 -> 140.875 | S42: =SUM(S34:S41)/8 -> 129.625 | T42: =SUM(T34:T41) -> 61
E43: Net Total/Avg | F43: =SUM(F34:F41,F23:F32,F8:F21) -> 474 | G43: =SUM(G34:G41,G23:G32,G8:G21) -> 2782 | H43: =AVERAGE(H34:H41,H23:H32,H8:H21) -> 310.90625 | I43: =AVERAGE(I34:I41,I23:I32,I8:I21) -> 5.90625 | J43: =SUM(J34:J41,J23:J32,J8:J21) -> 474 | K43: =SUM(K34:K41,K23:K32,K8:K21) -> 148 | L43: =SUM(L34:L41,L23:L32,L8:L21)/32 -> 345.34375 | M43: =SUM(M34:M41,M23:M32,M8:M21) -> 255 | N43: =SUM(N23:N32,N34:N41,N8:N21) -> 352 | O43: =SUM(O34:O41,O23:O32,O8:O21)/32 -> 980.96875 | P43: =SUM(P34:P41,P23:P32,P8:P21) -> 302 | Q43: =SUM(Q34:Q41,Q23:Q32,Q8:Q21) -> 65 | R43: =SUM(R34:R41,R23:R32,R8:R21)/32 -> 151.5625 | S43: =SUM(S34:S41,S23:S32,S8:S21)/32 -> 114.40625 | T43: =SUM(T42,T33,T22) -> 229

Sheet Structural_Features
D3: Query | E3: FedBench | I3: LargeRDFBench | N3: #TP | T3: #Vertices | Z3: #Join Vertices | AF3: #Mean Join Vertices Degree
E4: #TP | F4: # Vertices | G4: #Join Vertices | H4: Mean Join Vertex Degree | I4: #TP | J4: # Vertices | K4: #Join Vertices | L4: Mean Join Vertex Degree | N4: Query | O4: FedBench | P4: FedBench-Mean | Q4: LargeRDFBench | R4: LargeRDFBench-Mean | T4: Query | U4: FedBench | V4: FedBench-Mean | W4: LargeRDFBench | X4: LargeRDFBench-Mean | Z4: Query | AA4: FedBench | AB4: FedBench-Mean | AC4: LargeRDFBench | AD4: LargeRDFBench-Mean | AF4: Query | AG4: FedBench | AH4: FedBench-Mean | AI4: LargeRDFBench | AJ4: LargeRDFBench-Mean
D5: S1 | E5: 3 | F5: 8 | G5: 1 | H5: 2 | I5: 3 | J5: 8 | K5: 1 | L5: 2 | N5: S1 | O5: 3 | P5: =AVERAGE(O5:O18) -> 4.3571429 | Q5: 3 | R5: =AVERAGE(Q5:Q36) -> 6.6875 | T5: S1 | U5: 8 | V5: =AVERAGE(U5:U18) -> 9.9285714 | W5: 8 | X5: =AVERAGE(W5:W36) -> 14.6875 | Z5: S1 | AA5: 1 | AB5: =AVERAGE(AA5:AA18) -> 2.6428571 | AC5: 1 | AD5: =AVERAGE(AC5:AC36) -> 3.4375 | AF5: S1 | AG5: 2 | AH5: =AVERAGE(AG5:AG18) -> 2.1853846 | AI5: 2 | AJ5: =AVERAGE(AI5:AI36) -> 2.5683871
D6: S2 | E6: 3 | F6: 7 | G6: 2 | H6: 2 | I6: 3 | J6: 7 | K6: 2 | L6: 2 | N6: S2 | O6: 3 | P6: 4.3571429 | Q6: 3 | R6: 6.6875 | T6: S2 | U6: 7 | V6: 9.9285714 | W6: 7 | X6: 14.6875 | Z6: S2 | AA6: 2 | AB6: 2.6428571 | AC6: 2 | AD6: 3.5 | AF6: S2 | AG6: 2 | AH6: 2.1853846 | AI6: 2 | AJ6: 2.5583871
D7: S3 | E7: 5 | F7: 11 | G7: 2 | H7: 3 | I7: 5 | J7: 11 | K7: 2 | L7: 3 | N7: S3 | O7: 5 | P7: 4.3571429 | Q7: 5 | R7: =R6 -> 6.6875 | T7: S3 | U7: 11 | V7: 9.9285714 | W7: 11 | X7: 14.6875 | Z7: S3 | AA7: 2 | AB7: 2.6428571 | AC7: 2 | AD7: =AD6 -> 3.5 | AF7: S3 | AG7: 3 | AH7: 2.1853846 | AI7: 3 | AJ7: 2.5583871
D8: S4 | E8: 5 | F8: 10 | G8: 5 | H8: 2 | I8: 5 | J8: 10 | K8: 5 | L8: 2 | N8: S4 | O8: 5 | P8: 4.3571429 | Q8: 5 | R8: =R7 -> 6.6875 | T8: S4 | U8: 10 | V8: 9.9285714 | W8: 10 | X8: 14.6875 | Z8: S4 | AA8: 5 | AB8: 2.6428571 | AC8: 5 | AD8: =AD7 -> 3.5 | AF8: S4 | AG8: 2 | AH8: 2.1853846 | AI8: 2 | AJ8: 2.5583871
D9: S5 | E9: 4 | F9: 9 | G9: 3 | H9: 2 | I9: 4 | J9: 9 | K9: 3 | L9: 2 | N9: S5 | O9: 4 | P9: 4.3571429 | Q9: 4 | R9: =R8 -> 6.6875 | T9: S5 | U9: 9 | V9: 9.9285714 | W9: 9 | X9: 14.6875 | Z9: S5 | AA9: 3 | AB9: 2.6428571 | AC9: 3 | AD9: =AD8 -> 3.5 | AF9: S5 | AG9: 2 | AH9: 2.1853846 | AI9: 2 | AJ9: 2.5583871
D10: S6 | E10: 4 | F10: 9 | G10: 3 | H10: 2 | I10: 4 | J10: 9 | K10: 3 | L10: 2 | N10: S6 | O10: 4 | P10: 4.3571429 | Q10: 4 | R10: =R9 -> 6.6875 | T10: S6 | U10: 9 | V10: 9.9285714 | W10: 9 | X10: 14.6875 | Z10: S6 | AA10: 3 | AB10: 2.6428571 | AC10: 3 | AD10: =AD9 -> 3.5 | AF10: S6 | AG10: 2 | AH10: 2.1853846 | AI10: 2 | AJ10: 2.5583871
D11: S7 | E11: 4 | F11: 9 | G11: 3 | H11: 2 | I11: 4 | J11: 9 | K11: 3 | L11: 2 | N11: S7 | O11: 4 | P11: 4.3571429 | Q11: 4 | R11: =R10 -> 6.6875 | T11: S7 | U11: 9 | V11: 9.9285714 | W11: 9 | X11: 14.6875 | Z11: S7 | AA11: 3 | AB11: 2.6428571 | AC11: 3 | AD11: =AD10 -> 3.5 | AF11: S7 | AG11: 2 | AH11: 2.1853846 | AI11: 2 | AJ11: 2.5583871
D12: S8 | E12: 2 | F12: 6 | G12: 0 | H12: NA | I12: 2 | J12: 6 | K12: 0 | L12: NA | N12: S8 | O12: 2 | P12: 4.3571429 | Q12: 2 | R12: =R11 -> 6.6875 | T12: S8 | U12: 6 | V12: 9.9285714 | W12: 6 | X12: 14.6875 | Z12: S8 | AA12: 0 | AB12: 2.6428571 | AC12: 0 | AD12: =AD11 -> 3.5 | AF12: S8 | AG12: NA | AH12: 2.1853846 | AI12: NA | AJ12: 2.5583871
D13: S9 | E13: 3 | F13: 8 | G13: 1 | H13: 2 | I13: 3 | J13: 8 | K13: 1 | L13: 2 | N13: S9 | O13: 3 | P13: 4.3571429 | Q13: 3 | R13: =R12 -> 6.6875 | T13: S9 | U13: 8 | V13: 9.9285714 | W13: 8 | X13: 14.6875 | Z13: S9 | AA13: 1 | AB13: 2.6428571 | AC13: 1 | AD13: =AD12 -> 3.5 | AF13: S9 | AG13: 2 | AH13: 2.1853846 | AI13: 2 | AJ13: 2.5583871
D14: S10 | E14: 5 | F14: 11 | G14: 3 | H14: 2.33 | I14: 5 | J14: 11 | K14: 3 | L14: 2.33 | N14: S10 | O14: 5 | P14: 4.3571429 | Q14: 5 | R14: =R13 -> 6.6875 | T14: S10 | U14: 11 | V14: 9.9285714 | W14: 11 | X14: 14.6875 | Z14: S10 | AA14: 3 | AB14: 2.6428571 | AC14: 3 | AD14: =AD13 -> 3.5 | AF14: S10 | AG14: 2.33 | AH14: 2.1853846 | AI14: 2.33 | AJ14: 2.5583871
D15: S11 | E15: 7 | F15: 15 | G15: 4 | H15: 2.5 | I15: 7 | J15: 15 | K15: 4 | L15: 2.5 | N15: S11 | O15: 7 | P15: 4.3571429 | Q15: 7 | R15: =R14 -> 6.6875 | T15: S11 | U15: 15 | V15: 9.9285714 | W15: 15 | X15: 14.6875 | Z15: S11 | AA15: 4 | AB15: 2.6428571 | AC15: 4 | AD15: =AD14 -> 3.5 | AF15: S11 | AG15: 2.5 | AH15: 2.1853846 | AI15: 2.5 | AJ15: 2.5583871
D16: S12 | E16: 6 | F16: 13 | G16: 4 | H16: 2.25 | I16: 6 | J16: 13 | K16: 4 | L16: 2.25 | N16: S12 | O16: 6 | P16: 4.3571429 | Q16: 6 | R16: =R15 -> 6.6875 | T16: S12 | U16: 13 | V16: 9.9285714 | W16: 13 | X16: 14.6875 | Z16: S12 | AA16: 4 | AB16: 2.6428571 | AC16: 4 | AD16: =AD15 -> 3.5 | AF16: S12 | AG16: 2.25 | AH16: 2.1853846 | AI16: 2.25 | AJ16: 2.5583871
D17: S13 | E17: 5 | F17: 11 | G17: 3 | H17: 2.33 | I17: 5 | J17: 11 | K17: 3 | L17: 2.33 | N17: S13 | O17: 5 | P17: 4.3571429 | Q17: 5 | R17: =R16 -> 6.6875 | T17: S13 | U17: 11 | V17: 9.9285714 | W17: 11 | X17: 14.6875 | Z17: S13 | AA17: 3 | AB17: 2.6428571 | AC17: 3 | AD17: =AD16 -> 3.5 | AF17: S13 | AG17: 2.33 | AH17: 2.1853846 | AI17: 2.33 | AJ17: 2.5583871
D18: S14 | E18: 5 | F18: 12 | G18: 3 | H18: 2 | I18: 5 | J18: 12 | K18: 3 | L18: 2 | N18: S14 | O18: 5 | P18: 4.3571429 | Q18: 5 | R18: =R17 -> 6.6875 | T18: S14 | U18: 12 | V18: 9.9285714 | W18: 12 | X18: 14.6875 | Z18: S14 | AA18: 3 | AB18: 2.6428571 | AC18: 3 | AD18: =AD17 -> 3.5 | AF18: S14 | AG18: 2 | AH18: 2.1853846 | AI18: 2 | AJ18: 2.5583871
D19: C1 | I19: 8 | J19: 18 | K19: 4 | L19: 2.5 | N19: C1 | Q19: 8 | R19: =R18 -> 6.6875 | T19: C1 | W19: 18 | X19: 14.6875 | Z19: C1 | AC19: 4 | AD19: =AD18 -> 3.5 | AF19: C1 | AI19: 2.5 | AJ19: 2.5583871
D20: C2 | I20: 8 | J20: 19 | K20: 4 | L20: 2.25 | N20: C2 | Q20: 8 | R20: =R19 -> 6.6875 | T20: C2 | W20: 19 | X20: 14.6875 | Z20: C2 | AC20: 4 | AD20: =AD19 -> 3.5 | AF20: C2 | AI20: 2.25 | AJ20: 2.5583871
D21: C3 | I21: 8 | J21: 18 | K21: 4 | L21: 2.5 | N21: C3 | Q21: 8 | R21: =R20 -> 6.6875 | T21: C3 | W21: 18 | X21: 14.6875 | Z21: C3 | AC21: 4 | AD21: =AD20 -> 3.5 | AF21: C3 | AI21: 2.5 | AJ21: 2.5583871
D22: C4 | I22: 12 | J22: 26 | K22: 2 | L22: 6 | N22: C4 | Q22: 12 | R22: =R21 -> 6.6875 | T22: C4 | W22: 26 | X22: 14.6875 | Z22: C4 | AC22: 2 | AD22: =AD21 -> 3.5 | AF22: C4 | AI22: 6 | AJ22: 2.5583871
D23: C5 | I23: 8 | J23: 17 | K23: 5 | L23: 2.4 | N23: C5 | Q23: 8 | R23: =R22 -> 6.6875 | T23: C5 | W23: 17 | X23: 14.6875 | Z23: C5 | AC23: 5 | AD23: =AD22 -> 3.5 | AF23: C5 | AI23: 2.4 | AJ23: 2.5583871
D24: C6 | I24: 9 | J24: 18 | K24: 5 | L24: 2.8 | N24: C6 | Q24: 9 | R24: =R23 -> 6.6875 | T24: C6 | W24: 18 | X24: 14.6875 | Z24: C6 | AC24: 5 | AD24: =AD23 -> 3.5 | AF24: C6 | AI24: 2.8 | AJ24: 2.5583871
D25: C7 | I25: 9 | J25: 19 | K25: 6 | L25: 2.33 | N25: C7 | Q25: 9 | R25: =R24 -> 6.6875 | T25: C7 | W25: 19 | X25: 14.6875 | Z25: C7 | AC25: 6 | AD25: =AD24 -> 3.5 | AF25: C7 | AI25: 2.33 | AJ25: 2.5583871
D26: C8 | I26: 11 | J26: 24 | K26: 4 | L26: 3.25 | N26: C8 | Q26: 11 | R26: =R25 -> 6.6875 | T26: C8 | W26: 24 | X26: 14.6875 | Z26: C8 | AC26: 4 | AD26: =AD25 -> 3.5 | AF26: C8 | AI26: 3.25 | AJ26: 2.5583871
D27: C9 | I27: 9 | J27: 20 | K27: 4 | L27: 2.75 | N27: C9 | Q27: 9 | R27: =R26 -> 6.6875 | T27: C9 | W27: 20 | X27: 14.6875 | Z27: C9 | AC27: 4 | AD27: =AD26 -> 3.5 | AF27: C9 | AI27: 2.75 | AJ27: 2.5583871
D28: C10 | I28: 10 | J28: 21 | K28: 5 | L28: 2.8 | N28: C10 | Q28: 10 | R28: =R27 -> 6.6875 | T28: C10 | W28: 21 | X28: 14.6875 | Z28: C10 | AC28: 5 | AD28: =AD27 -> 3.5 | AF28: C10 | AI28: 2.8 | AJ28: 2.5583871
D29: L1 | I29: 6 | J29: 14 | K29: 4 | L29: 2 | N29: L1 | Q29: 6 | R29: =R28 -> 6.6875 | T29: L1 | W29: 14 | X29: 14.6875 | Z29: L1 | AC29: 4 | AD29: =AD28 -> 3.5 | AF29: L1 | AI29: 2 | AJ29: 2.5583871
D30: L2 | I30: 6 | J30: 13 | K30: 2 | L30: 3.5 | N30: L2 | Q30: 6 | R30: =R29 -> 6.6875 | T30: L2 | W30: 13 | X30: 14.6875 | Z30: L2 | AC30: 2 | AD30: =AD29 -> 3.5 | AF30: L2 | AI30: 3.5 | AJ30: 2.5583871
... D36: L8 | I36: 8 | J36: 18 | K36: 4 | L36: 2.5 | N36: L8 | Q36: 8 | R36: =R35 -> 6.6875 | T36: L8 | W36: 18 | X36: 14.6875 | Z36: L8 | AC36: 4 | AD36: =AD35 -> 3.5 | AF36: L8 | AI36: 2.5 | AJ36: 2.5583871
D37: Std. Dev | E37: =_xlfn.STDEV.S(E5:E18) -> 1.3363062 | F37: =_xlfn.STDEV.S(F5:F18) -> 2.4326082 | G37: =_xlfn.STDEV.S(G5:G18) -> 1.3363062 | H37: =_xlfn.STDEV.S(H5:H11,H13:H18) -> 0.30048892 | I37: =_xlfn.STDEV.S(I5:I36) -> 2.6449892 | J37: =_xlfn.STDEV.S(J5:J36) -> 5.3881591 | K37: =_xlfn.STDEV.S(K5:K36) -> 1.4138571 | L37: =_xlfn.STDEV.S(L13:L36,L5:L11) -> 0.75830116
D38: Variance | E38: =_xlfn.VAR.S(E5:E18) -> 1.7857143 | F38: =_xlfn.VAR.S(F5:F18) -> 5.9175824 | G38: =_xlfn.VAR.S(G5:G18) -> 1.7857143 | H38: =_xlfn.VAR.S(H13:H18,H5:H11) -> 0.09029359 | I38: =_xlfn.VAR.S(I5:I36) -> 6.9959677 | J38: =_xlfn.VAR.S(J5:J36) -> 29.032258 | K38: =_xlfn.VAR.S(K5:K36) -> 1.9989919 | L38: =_xlfn.VAR.S(L13:L36,L5:L11) -> 0.57502065
G41: Queries Distribution with respect to join vertex type
F42: Star | G42: Path | H42: Hybrid | I42: Sink
D43: Fedbench | F43: 12 | G43: 8 | H43: 2 | I43: 5
D44: LargeRDFBench | F44: 24 | G44: 25 | H44: 13 | I44: 13
G46: % Queries Distribution with respect to join vertex type
F47: Star | G47: Path | H47: Hybrid | I47: Sink
D48: FedBench | F48: =F43/14*100 -> 85.714286 | G48: =G43/14*100 -> 57.142857 | H48: =H43/14*100 -> 14.285714 | I48: =I43/14*100 -> 35.714286
D49: LargeRDFBench | F49: =100*F44/32 -> 75 | G49: =100*G44/32 -> 78.125 | H49: =100*H44/32 -> 40.625 | I49: =100*I44/32 -> 40.625
J52: Distribution with respect to SPARQL clauses. FedBench total SPARQL endpoint federation queries 14 , LargeRDFBench 32
...

Sheet Data Driven_Features
T2: =_xlfn.STDEV.S(S5:S18) -> 3.4105525 | U2: =_xlfn.STDEV.S(U5:U36) -> 3.4448419 | AE2: =_xlfn.STDEV.S(AE5:AE18) -> 0.66299354 | AG2: =_xlfn.STDEV.S(AG5:AG36) -> 0.55266947
B3: Query | C3: FedBench | G3: LargeRDFBench | L3: #Results | R3: # Relevant Sources | X3: Datasets based Mean Filtered Triple Pattern Selectivity | AD3: # Minimum number of sources
C4: #Results | D4: #Scources Span | G4: #Results | H4: #Scources Span | L4: Query | M4: FedBench | N4: FedBench-Mean | O4: LargeRDFBench | P4: LargeRDFBench-Mean | R4: Query | S4: FedBench | T4: FedBench-Mean | U4: LargeRDFBench | V4: LargeRDFBench-Mean | AA4: LargeRDFBench | AD4: Query | AE4: FedBench | AF4: FedBench-Mean | AG4: LargeRDFBench | AH4: LargeRDFBench-Mean
B5: S1 | C5: 90 | D5: 2 | G5: 90 | H5: 2 | L5: S1 | M5: 90 | N5: =AVERAGE(M5:M18) -> 907 | O5: 90 | P5: =AVERAGE(O5:O36) -> 59754.25 | R5: S1 | S5: 2 | T5: =AVERAGE(S5:S18) -> 5.6428571 | U5: 2 | V5: =AVERAGE(U5:U36) -> 6.0625 | X5: Query | Y5: Mean | Z5: F.S.D | AA5: Mean | AB5: B.S.D | AD5: S1 | AE5: 2 | AF5: =AVERAGE(AE5:AE18) -> 2.1428571 | AG5: 2 | AH5: =AVERAGE(AG5:AG36) -> 2.21875 | AJ5: =_xlfn.STDEV.S(AE5:AE18) -> 0.66299354
B6: S2 | C6: 1 | D6: 2 | G6: 1 | H6: 2 | L6: S2 | M6: 1 | N6: 907 | O6: 1 | P6: 59754.25 | R6: S2 | S6: 2 | T6: 5.6428571 | U6: 2 | V6: 6.0625 | X6: S1 | Y6: 0.33333493 | Z6: 0.57734889 | AA6: 0.33333493 | AB6: 0.57734889 | AD6: S2 | AE6: 2 | AF6: 2.1428571 | AG6: 2 | AH6: 2.21875 | AJ6: =_xlfn.STDEV.S(AG5:AG36) -> 0.55266947
B7: S3 | C7: 2 | D7: 5 | G7: 2 | H7: 5 | L7: S3 | M7: 2 | N7: 907 | O7: 2 | P7: =P6 -> 59754.25 | R7: S3 | S7: 8 | T7: 5.6428571 | U7: 8 | V7: =V6 -> 6.0625 | X7: S2 | Y7: 0.0073916589 | Z7: 0.012800125 | AA7: 0.0073916589 | AB7: 0.012800125 | AD7: S3 | AE7: 2 | AF7: 2.1428571 | AG7: 2 | AH7: =AH6 -> 2.21875
B8: S4 | C8: 1 | D8: 5 | G8: 1 | H8: 5 | L8: S4 | M8: 1 | N8: 907 | O8: 1 | P8: =P7 -> 59754.25 | R8: S4 | S8: 8 | T8: 5.6428571 | U8: 8 | V8: =V7 -> 6.0625 | X8: S3 | Y8: 0.0088895714 | Z8: 0.011743408 | AA8: 0.0088895714 | AB8: 0.011743408 | AD8: S4 | AE8: 2 | AF8: 2.1428571 | AG8: 2 | AH8: =AH7 -> 2.21875
B9: S5 | C9: 2 | D9: 5 | G9: 2 | H9: 5 | L9: S5 | M9: 2 | N9: 907 | O9: 2 | P9: =P8 -> 59754.25 | R9: S5 | S9: 8 | T9: 5.6428571 | U9: 8 | V9: =V8 -> 6.0625 | X9: S4 | Y9: 0.019295158 | Z9: 0.011637102 | AA9: 0.019295158 | AB9: 0.011637102 | AD9: S5 | AE9: 2 | AF9: 2.1428571 | AG9: 2 | AH9: =AH8 -> 2.21875
B10: S6 | C10: 11 | D10: 4 | G10: 11 | H10: 4 | L10: S6 | M10: 11 | N10: 907 | O10: 11 | P10: =P9 -> 59754.25 | R10: S6 | S10: 6 | T10: 5.6428571 | U10: 6 | V10: =V9 -> 6.0625 | X10: S5 | Y10: 0.0061693763 | Z10: 0.01013834 | AA10: 0.0061693763 | AB10: 0.01013834 | AD10: S6 | AE10: 4 | AF10: 2.1428571 | AG10: 4 | AH10: =AH9 -> 2.21875 | AJ10: =AVERAGE(U19:U28) -> 7.8
B11: S7 | C11: 1 | D11: 5 | G11: 1 | H11: 5 | L11: S7 | M11: 1 | N11: 907 | O11: 1 | P11: =P10 -> 59754.25 | R11: S7 | S11: 8 | T11: 5.6428571 | U11: 8 | V11: =V10 -> 6.0625 | X11: S6 | Y11: 0.019395937 | Z11: 0.017605357 | AA11: 0.019395937 | AB11: 0.017605357 | AD11: S7 | AE11: 2 | AF11: 2.1428571 | AG11: 2 | AH11: =AH10 -> 2.21875 | AJ11: =AVERAGE(AG19:AG28) -> 2.4
B12: S8 | C12: 1159 | D12: 2 | G12: 1159 | H12: 2 | L12: S8 | M12: 1159 | N12: 907 | O12: 1159 | P12: =P11 -> 59754.25 | R12: S8 | S12: 1 | T12: 5.6428571 | U12: 1 | V12: =V11 -> 6.0625 | X12: S7 | Y12: 0.020198747 | Z12: 0.01533511 | AA12: 0.020198747 | AB12: 0.01533511 | AD12: S8 | AE12: 1 | AF12: 2.1428571 | AG12: 1 | AH12: =AH11 -> 2.21875
B13: S9 | C13: 333 | D13: 4 | G13: 333 | H13: 4 | L13: S9 | M13: 333 | N13: 907 | O13: 333 | P13: =P12 -> 59754.25 | R13: S9 | S13: 13 | T13: 5.6428571 | U13: 13 | V13: =V12 -> 6.0625 | X13: S8 | Y13: 0.00112084 | Z13: 0.001585107 | AA13: 0.00112084 | AB13: 0.001585107 | AD13: S9 | AE13: 2 | AF13: 2.1428571 | AG13: 2 | AH13: =AH12 -> 2.21875 | AJ13: =AVERAGE(U29:U36) -> 4.625
B14: S10 | C14: 9054 | D14: 2 | G14: 9054 | H14: 2 | L14: S10 | M14: 9054 | N14: 907 | O14: 9054 | P14: =P13 -> 59754.25 | R14: S10 | S14: 8 | T14: 5.6428571 | U14: 8 | V14: =V13 -> 6.0625 | X14: S9 | Y14: 0.3335448 | Z14: 0.57716721 | AA14: 0.3335448 | AB14: 0.57716721 | AD14: S10 | AE14: 2 | AF14: 2.1428571 | AG14: 2 | AH14: =AH13 -> 2.21875 | AJ14: =AVERAGE(AG29:AG36) -> 2.125
B15: S11 | C15: 3 | D15: 2 | G15: 3 | H15: 2 | L15: S11 | M15: 3 | N15: 907 | O15: 3 | P15: =P14 -> 59754.25 | R15: S11 | S15: 2 | T15: 5.6428571 | U15: 2 | V15: =V14 -> 6.0625 | X15: S10 | Y15: 0.016010968 | Z15: 0.0089269498 | AA15: 0.016010968 | AB15: 0.0089269498 | AD15: S11 | AE15: 2 | AF15: 2.1428571 | AG15: 2 | AH15: =AH14 -> 2.21875
B16: S12 | C16: 393 | D16: 3 | G16: 393 | H16: 3 | L16: S12 | M16: 393 | N16: 907 | O16: 393 | P16: =P15 -> 59754.25 | R16: S12 | S16: 5 | T16: 5.6428571 | U16: 5 | V16: =V15 -> 6.0625 | X16: S11 | Y16: 0.0066284917 | Z16: 0.0074170773 | AA16: 0.0066284917 | AB16: 0.0074170773 | AD16: S12 | AE16: 3 | AF16: 2.1428571 | AG16: 3 | AH16: =AH15 -> 2.21875
B17: S13 | C17: 28 | D17: 3 | G17: 28 | H17: 3 | L17: S13 | M17: 28 | N17: 907 | O17: 28 | P17: =P16 -> 59754.25 | R17: S13 | S17: 5 | T17: 5.6428571 | U17: 5 | V17: =V16 -> 6.0625 | X17: S12 | Y17: 0.01217423 | Z17: 0.0085514545 | AA17: 0.01217423 | AB17: 0.0085514545 | AD17: S13 | AE17: 2 | AF17: 2.1428571 | AG17: 2 | AH17: =AH16 -> 2.21875
B18: S14 | C18: 1620 | D18: 3 | G18: 1620 | H18: 3 | L18: S14 | M18: 1620 | N18: 907 | O18: 1620 | P18: =P17 -> 59754.25 | R18: S14 | S18: 3 | T18: 5.6428571 | U18: 3 | V18: =V17 -> 6.0625 | X18: S13 | Y18: 0.014815076 | Z18: 0.015589935 | AA18: 0.014815076 | AB18: 0.015589935 | AD18: S14 | AE18: 2 | AF18: 2.1428571 | AG18: 2 | AH18: =AH17 -> 2.21875
B19: C1 | G19: 1000 | H19: 5 | L19: C1 | O19: 1000 | P19: =P18 -> 59754.25 | R19: C1 | U19: 5 | V19: =V18 -> 6.0625 | X19: S14 | Y19: 0.012452045 | Z19: 0.014839445 | AA19: 0.012452045 | AB19: 0.014839445 | AD19: C1 | AG19: 2 | AH19: =AH18 -> 2.21875
B20: C2 | G20: 4 | H20: 5 | L20: C2 | O20: 4 | P20: =P19 -> 59754.25 | R20: C2 | U20: 5 | V20: =V19 -> 6.0625 | X20: C1 | AA20: 0.010779222 | AB20: 0.0085596229 | AD20: C2 | AG20: 3 | AH20: =AH19 -> 2.21875
B21: C3 | G21: 9 | H21: 3 | L21: C3 | O21: 9 | P21: =P20 -> 59754.25 | R21: C3 | U21: 8 | V21: =V20 -> 6.0625 | X21: C2 | AA21: 0.0097246598 | AB21: 0.0080409788 | AD21: C3 | AG21: 3 | AH21: =AH20 -> 2.21875
B22: C4 | G22: 50 | H22: 8 | L22: C4 | O22: 50 | P22: =P21 -> 59754.25 | R22: C4 | U22: 8 | V22: =V21 -> 6.0625 | X22: C3 | AA22: 0.020214493 | AB22: 0.014707891 | AD22: C4 | AG22: 3 | AH22: =AH21 -> 2.21875
B23: C5 | G23: 500 | H23: 8 | L23: C5 | O23: 500 | P23: =P22 -> 59754.25 | R23: C5 | U23: 13 | V23: =V22 -> 6.0625 | X23: C4 | AA23: 0.012412695 | AB23: 0.015408137 | AD23: C5 | AG23: 2 | AH23: =AH22 -> 2.21875
B24: C6 | G24: 148 | H24: 2 | L24: C6 | O24: 148 | P24: =P23 -> 59754.25 | R24: C6 | U24: 8 | V24: =V23 -> 6.0625 | X24: C5 | AA24: 0.018655228 | AB24: 0.018607939 | AD24: C6 | AG24: 2 | AH24: =AH23 -> 2.21875
B25: C7 | G25: 112 | H25: 2 | L25: C7 | O25: 112 | P25: =P24 -> 59754.25 | R25: C7 | U25: 5 | V25: =V24 -> 6.0625 | X25: C6 | AA25: 0.022971132 | AB25: 0.0070587251 | AD25: C7 | AG25: 2 | AH25: =AH24 -> 2.21875
B26: C8 | G26: 3067 | H26: 3 | L26: C8 | O26: 3067 | P26: =P25 -> 59754.25 | R26: C8 | U26: 13 | V26: =V25 -> 6.0625 | X26: C7 | AA26: 0.014815749 | AB26: 0.013931895 | AD26: C8 | AG26: 2 | AH26: =AH25 -> 2.21875
B27: C9 | G27: 100 | H27: 3 | L27: C9 | O27: 100 | P27: =P26 -> 59754.25 | R27: C9 | U27: 8 | V27: =V26 -> 6.0625 | X27: C8 | AA27: 0.012449596 | AB27: 0.018444083 | AD27: C9 | AG27: 2 | AH27: =AH26 -> 2.21875
B28: C10 | G28: 102 | H28: 3 | L28: C10 | O28: 102 | P28: =P27 -> 59754.25 | R28: C10 | U28: 5 | V28: =V27 -> 6.0625 | X28: C9 | AA28: 0.01107262 | AB28: 0.0088030194 | AD28: C10 | AG28: 3 | AH28: =AH27 -> 2.21875
B29: L1 | G29: 227192 | H29: 3 | L29: L1 | O29: 227192 | P29: =P28 -> 59754.25 | R29: L1 | U29: 3 | V29: =V28 -> 6.0625 | X29: C10 | AA29: 0.0027120484 | AB29: 0.0035752279 | AD29: L1 | AG29: 2 | AH29: =AH28 -> 2.21875
B30: L2 | G30: 152899 | H30: 3 | L30: L2 | O30: 152899 | P30: =P29 -> 59754.25 | R30: L2 | U30: 3 | V30: =V29 -> 6.0625 | X30: L1 | AA30: 0.19222037 | AB30: 0.4002405 | AD30: L2 | AG30: 2 | AH30: =AH29 -> 2.21875
B31: L3 | G31: 257158 | H31: 3 | L31: L3 | O31: 257158 | P31: =P30 -> 59754.25 | R31: L3 | U31: 3 | V31: =V30 -> 6.0625 | X31: L2 | AA31: 0.28678674 | AB31: 0.45296103 | AD31: L3 | AG31: 2 | AH31: =AH30 -> 2.21875
... B36: L8 | G36: 306705 | H36: 3 | L36: L8 | O36: 306705 | P36: =P35 -> 59754.25 | R36: L8 | U36: 3 | V36: =V35 -> 6.0625 | X36: L7 | AA36: 0.20069629 | AB36: 0.44682464 | AD36: L8 | AG36: 2 | AH36: =AH35 -> 2.21875
B37: Std. Dev | C37: =_xlfn.STDEV.S(C5:C18) -> 2397.1116 | D37: =_xlfn.STDEV.S(D5:D18) -> 1.2774459 | E37: =_xlfn.STDEV.S(E5:E18) -> #DIV/0! | F37: =_xlfn.STDEV.S(F5:F11,F13:F18) -> #DIV/0! | G37: =_xlfn.STDEV.S(G5:G36) -> 113763.42 | H37: =_xlfn.STDEV.S(H5:H36) -> 1.5368458 | I37: =_xlfn.STDEV.S(I5:I36) -> #DIV/0! | J37: =_xlfn.STDEV.S(J13:J36,J5:J11) -> #DIV/0! | X37: L8 | AA37: 0.27809356 | AB37: 0.38255436
B38: Variance | C38: =_xlfn.VAR.S(C5:C18) -> 5746144.2 | D38: =_xlfn.VAR.S(D5:D18) -> 1.6318681 | E38: =_xlfn.VAR.S(E5:E18) -> #DIV/0! | F38: =_xlfn.VAR.S(F13:F18,F5:F11) -> #DIV/0! | G38: =_xlfn.VAR.S(G5:G36) -> 1.2942115e+10 | H38: =_xlfn.VAR.S(H5:H36) -> 2.3618952 | I38: =_xlfn.VAR.S(I5:I36) -> #DIV/0! | J38: =_xlfn.VAR.S(J13:J36,J5:J11) -> #DIV/0! | X38: Mean | Y38: =AVERAGE(Y6:Y19) -> 0.057958702 | Z38: =AVERAGE(Z6:Z19) -> 0.092191822 | AA38: =AVERAGE(AA6:AA37) -> 0.10287299 | AB38: =AVERAGE(AB6:AB37) -> 0.14660383
O40: mean BGP-restricted Triple pattern selectivity | S40: mean Join-restricted Triple pattern selectivity | Y40: mean Triple pattern selectivity | AB40: Mean TP selectivities Standard deviations
O41: Query | P41: FedBench | Q41: LargeRDFBench | R41: S.D. | S41: Query | T41: FedBench | U41: LargeRDFBench | V41: S.D. | X41: Query | Y41: FedBench | Z41: LargeRDFBench | AB41: Query | AC41: FedBench | AD41: LargeRDFBench
O42: S1 | P42: 0.66666667 | Q42: =P42 -> 0.66666667 | R42: 1 | S42: S1 | T42: 0.33333333 | U42: =T42 -> 0.33333333 | V42: 0.70710678 | W42: =IF(U42<0,-LN(-U42),LN(U42)) -> -1.0986123 | X42: S1 | Y42: 0.33333493 | Z42: 0.33333493 | AB42: S1 | AC42: 0.57734889 | AD42: 0.57734889 | AG42: =Q42 -> 0.66666667 | AH42: =U42 -> 0.33333333
O43: S2 | P43: 0.66671152 | Q43: =P43 -> 0.66671152 | R43: 0.70707507 | S43: S2 | T43: 0.33337818 | U43: =T43 -> 0.33337818 | V43: 0.74529583 | W43: =ABS(LOG10(U43)) -> 0.47706282 | X43: S2 | Y43: 0.0073916589 | Z43: 0.0073916589 | AB43: S2 | AC43: 0.012800125 | AD43: 0.012800125 | AG43: =Q43 -> 0.66671152 | AH43: =U43 -> 0.33337818
O44: S3 | P44: 0.00030687535 | Q44: =P44 -> 0.00030687535 | R44: 0.00050863255 | S44: S3 | T44: 0.00015343767 | U44: =T44 -> 0.00015343767 | V44: 0.00025431627 | W44: =ABS(LOG10(U44)) -> 3.814068 | X44: S3 | Y44: 0.0088895714 | Z44: 0.0088895714 | AB44: S3 | AC44: 0.011743408 | AD44: 0.011743408 | AG44: =Q44 -> 0.00030687535 | AH44: =U44 -> 0.00015343767
O45: S4 | P45: 0.2000292 | Q45: =P45 -> 0.2000292 | R45: 0.49998655 | S45: S4 | T45: 0.2000292 | U45: =T45 -> 0.2000292 | V45: 0.49998655 | W45: =ABS(LOG10(U45)) -> 0.69890659 | X45: S4 | Y45: 0.019295158 | Z45: 0.019295158 | AB45: S4 | AC45: 0.011637102 | AD45: 0.011637102 | AG45: =Q45 -> 0.2000292 | AH45: =U45 -> 0.2000292
O46: S5 | P46: 0.00066524908 | Q46: =P46 -> 0.00066524908 | R46: 0.0014015721 | S46: S5 | T46: 0.00064050631 | U46: =T46 -> 0.00064050631 | V46: 0.0014113799 | W46: =ABS(LOG10(U46)) -> 3.1934766 | X46: S5 | Y46: 0.0061693763 | Z46: 0.0061693763 | AB46: S5 | AC46: 0.01013834 | AD46: 0.01013834 | AG46: =Q46 -> 0.00066524908 | AH46: =U46 -> 0.00064050631
...

Sheet index const. and size
A1: in
F4: FedX | G4: SPLENDID | H4: LHD | I4: DARQ | J4: ANAPSID | K4: ADERIS | L4: Qtree | M4: FedSum
E5: Index Generation Time (min) | F5: NA | G5: 190 | H5: 193 | I5: 193 | J5: 6 | K5: 6 | L5: - | M5: 92
E6: Compression Ratio | F6: NA | G6: =100-G8/H11*100 -> 99.998783 | H6: =100-H8/H11*100 -> 99.998808 | I6: =100-I8/H11*100 -> 99.998808 | J6: =100-J8/H11*100 -> 99.999772 | K6: =100-K8/H11*100 -> 99.999772 | L6: 96 | M6: =100-M8/H11*100 -> 99.998837
E8: Index Size (KB) | G8: 587 | H8: 575 | I8: 575 | J8: 110 | K8: 110 | L8: From Qtree paper | M8: 561
G10: BigBench Size | H10: In KB
G11: 46 GB | H11: 48234496
G13: =100*G8/H11 -> 0.0012169714 | H13: =100*H8/H11 -> 0.0011920929 | I13: =100*I8/H11 -> 0.0011920929 | J13: =100*J8/H11 -> 0.00022805255 | K13: =100*K8/H11 -> 0.00022805255 | L13: =100*L8/H11 -> #VALUE! | M13: =100*M8/H11 -> 0.001163068

Sheet Runtimes_SPARQL1.1
A3: Query | B3: FedX(100% cached) | C3: ANAPSID
A4: S1 | B4: 205 | C4: 45 | D4: 10 | E4: 5
A5: S2 | B5: 165 | C5: 30 | D5: 3 | E5: 10 | S5: s6 and s7 query plan | U5: =B4-C4 -> 160
A6: S3 | B6: 179 | C6: 55 | D6: 15 | E6: 5 | U6: =B5-C5 -> 135
A7: S4 | B7: 159 | C7: 41 | D7: 5 | E7: 3 | U7: =B6-C6 -> 124
A8: S5 | B8: 160 | C8: 42 | D8: 3 | E8: 5 | U8: =B7-C7 -> 118
A9: S6 | B9: 1620 | C9: 2157 | D9: 100 | E9: 70 | U9: =B8-C8 -> 118
A10: S7 | B10: 712 | C10: 586 | D10: 70 | E10: 5 | U10: =B9-C9 -> -537
A11: S8 | B11: 385 | C11: 260 | D11: 30 | E11: 10 | U11: =B10-C10 -> 126
A12: S9 | B12: 305 | C12: 200 | D12: 25 | E12: 45 | U12: =B11-C11 -> 125
A13: S10 | B13: 6045 | C13: 13713 | D13: 90 | E13: 50 | U13: =B12-C12 -> 105
A14: S11 | B14: 153 | C14: 7429 | D14: 10 | E14: 150 | U14: =B13-C13 -> -7668
A15: S12 | B15: 2380 | C15: 3512 | D15: 20 | E15: 100 | U15: =B14-C14 -> -7276
A16: S13 | B16: 238 | C16: 5808 | D16: 5 | E16: 200 | U16: =B15-C15 -> -1132
A17: S14 | B17: 1604 | C17: 2964 | D17: 60 | E17: 50 | U17: =B16-C16 -> -5570
A18: Avg. | B18: =AVERAGE(B4:B17) -> 1022.1429 | C18: =AVERAGE(C4:C17) -> 2631.5714 | D18: s14 = 1054 | U18: =B17-C17 -> -1360
B19: FedX(100% cached) | C19: ANAPSID
A20: C1 | B20: RE | C20: 9987 | E20: CHECK
A21: C2 | B21: 4106 | C21: TO | E21: CHECK
A22: C3 | B22: 4234 | C22: TO | D22: 100 | H22: =100-100*67/142 -> 52.816901
A23: C4 | B23: 380 | C23: 145510 | D23: 70
A24: C5 | B24: TO | C24: RE
A25: C6 | B25: 30587 | C25: 19741 | D25: 200
A26: C7 | B26: 1012 | C26: 1213
A27: C8 | B27: 7162 | C27: 2534 | D27: 10
A28: C9 | B28: TO | C28: 20320
A29: C10 | B29: 2590 | C29: 16878 | D29: 10
A30: Avg. | B30: =AVERAGE(B29,B27,B26,B25,B23,B22,B21,B31) -> 306258.88 | C30: =AVERAGE(C29,C25:C27,C23,C20,C31) -> 370837.57
B31: 2400000 | C31: 2400000 | D31: C6=145
A32: RE = Runtime Error
A33: TO = Time out of 20 min | G33: =Runtimes_SPARQL1.0!E18 -> 47228.429 | H33: =Runtimes_SPARQL1.0!E31 -> 374057.29
A34: NS = Not Supported | G34: =100-100*C18/G33 -> 94.427993 | H34: =100-100*C30/H33 -> 0.86075433
A35: Note: 20 min was added while calculating averages for each time out.
G37: =Runtimes_SPARQL1.0!C31 -> 428496.75 | H37: =Runtimes_SPARQL1.0!C18 -> 4400.8571
A38: Query | B38: FedX(100% cached) | C38: ANAPSID | G38: =100-100*B30/G37 -> 28.527142 | H38: =100-100*B18/H37 -> 76.774005
A39: B1 | B39: TO | C39: TO
A40: B2 | B40: ZR | C40: TO
A41: B3 | B41: ZR | C41: TO
A42: B4 | B42: TO | C42: TO
A43: B5 | B43: ZR | C43: RE
...

Sheet dataset structuredness
B5: Dataset Structuredness
B6: Dataset | C6: FedBench | D6: FedBench-Mean | E6: LargeRDFBench | F6: LargeRDFBench-Mean
B7: ChEBI | C7: 0.34 | D7: =AVERAGE(C7:C21) -> 0.58075357 | E7: 0.34 | F7: =AVERAGE(E7:E19) -> 0.65769231
B8: DBPedia | C8: 0.196 | D8: =D7 -> 0.58075357 | E8: 0.196 | F8: =AVERAGE(E8:E20) -> 0.65195748
B9: DrugBank | C9: 0.726 | D9: =D8 -> 0.58075357 | E9: 0.726 | F9: =F8 -> 0.65195748
B10: Geo Names | C10: 0.518 | D10: =D9 -> 0.58075357 | E10: 0.518 | F10: =F9 -> 0.65195748
B11: Jamendo | C11: 0.961 | D11: =D10 -> 0.58075357 | E11: 0.961 | F11: =F10 -> 0.65195748
B12: KEGG | C12: 0.919 | D12: =D11 -> 0.58075357 | E12: 0.919 | F12: =F11 -> 0.65195748
B13: Linked Movies | C13: 0.729 | D13: =D12 -> 0.58075357 | E13: 0.729 | F13: =F12 -> 0.65195748
B14: NY Times | C14: 0.731 | D14: =D13 -> 0.58075357 | E14: 0.731 | F14: =F13 -> 0.65195748
B15: SW Dog Food | C15: 0.426 | D15: =D14 -> 0.58075357 | E15: 0.426 | F15: =F14 -> 0.65195748
B16: LTCGA-M | E16: 1 | F16: =F15 -> 0.65195748
B17: Affymetrix | E17: 0.506 | F17: =F16 -> 0.65195748
B18: LTCGA-E | E18: 1 | F18: =F17 -> 0.65195748
B19: LTCGA-A | E19: 0.498 | F19: =F18 -> 0.65195748
B20: Std. Deviation | C20: =_xlfn.STDEV.S(C7:C15) -> 0.26153574 | E20: =_xlfn.STDEV.S(E7:E19) -> 0.26544723

Sheet Query Stats
G4: Query | H4: Structure | I4: #Triple Patterns | J4: #Sources Span | K4: #Results | L4: #Join Vertices | M4: Mean Join Vertex Degree | N4: Mean Triple Pattern Selectivity | O4: Used SPARQL Clauses
G5: S1 | H5: Star | I5: 3 | J5: 2 | K5: 90 | L5: 1 | M5: 2 | N5: 0.33333493 | O5: UNION
G6: S2 | H6: Star | I6: 3 | J6: 2 | K6: 1 | L6: 2 | M6: 2 | N6: 0.007391659 | O6: X
G7: S3 | H7: Hybrid | I7: 5 | J7: 5 | K7: 2 | L7: 2 | M7: 3 | N7: 0.008889571 | O7: X
G8: S4 | H8: Path | I8: 5 | J8: 5 | K8: 1 | L8: 5 | M8: 2 | N8: 0.019295158 | O8: X
G9: S5 | H9: Path | I9: 4 | J9: 5 | K9: 2 | L9: 3 | M9: 2 | N9: 0.006169376 | O9: X
G10: S6 | H10: Path | I10: 4 | J10: 4 | K10: 11 | L10: 3 | M10: 2 | N10: 0.019395937 | O10: X
G11: S7 | H11: Path | I11: 4 | J11: 5 | K11: 1 | L11: 3 | M11: 2 | N11: 0.020198747 | O11: X
G12: S8 | H12: - | I12: 2 | J12: 2 | K12: 1159 | L12: 0 | M12: NA | N12: 0.00112084 | O12: UNION
G13: S9 | H13: Path | I13: 3 | J13: 4 | K13: 333 | L13: 1 | M13: 2 | N13: 0.3335448 | O13: UNION
G14: S10 | H14: Hybrid | I14: 5 | J14: 2 | K14: 9054 | L14: 3 | M14: 2.33 | N14: 0.016010968 | O14: X
G15: S11 | H15: Hybrid | I15: 7 | J15: 2 | K15: 3 | L15: 4 | M15: 2.5 | N15: 0.006628492 | O15: X
G16: S12 | H16: Hybrid | I16: 6 | J16: 3 | K16: 393 | L16: 4 | M16: 2.25 | N16: 0.01217423 | O16: X
G17: S13 | H17: Hybrid | I17: 5 | J17: 3 | K17: 28 | L17: 3 | M17: 2.33 | N17: 0.014815076 | O17: X
G18: S14 | H18: Hybrid | I18: 5 | J18: 3 | K18: 1620 | L18: 3 | M18: 2 | N18: 0.012452045 | O18: OPTIONAL
G19: Avg. | H19: - | I19: =AVERAGE(I5:I18) -> 4.3571429 | J19: =AVERAGE(J5:J18) -> 3.3571429 | K19: =AVERAGE(K5:K18) -> 907 | L19: =AVERAGE(L5:L18) -> 2.6428571 | M19: =AVERAGE(M5:M18) -> 2.1853846 | N19: =AVERAGE(N5:N18) -> 0.057958702 | O19: -
G20: C1 | H20: Hybrid | I20: 8 | J20: 5 | K20: 1000 | L20: 4 | M20: 2.5 | N20: 0.010779222 | O20: DISTINCT, FILTER, OPTIONAL, LIMIT
G21: C2 | H21: Hybrid | I21: 8 | J21: 5 | K21: 4 | L21: 4 | M21: 2.25 | N21: 0.00972466 | O21: OPTIONAL, FILTER
G22: C3 | H22: Hybrid | I22: 8 | J22: 3 | K22: 9 | L22: 4 | M22: 2.25 | N22: 0.020214493 | O22: DISTINCT, OPTIONAL
G23: C4 | H23: Star | I23: 12 | J23: 8 | K23: 50 | L23: 2 | M23: 6 | N23: 0.012412695 | O23: DISTINCT, OPTIONAL, LIMIT
G24: C5 | H24: Hybrid | I24: 8 | J24: 8 | K24: 500 | L24: 5 | M24: 2.4 | N24: 0.018655228 | O24: FILTER, LIMIT
G25: C6 | H25: Hybrid | I25: 9 | J25: 2 | K25: 148 | L25: 5 | M25: 2.8 | N25: 0.022971132 | O25: ORDER BY
G26: C7 | H26: Hybrid | I26: 9 | J26: 2 | K26: 112 | L26: 6 | M26: 2.33 | N26: 0.014815749 | O26: DISTINCT, OPTIONAL
G27: C8 | H27: Hybrid | I27: 11 | J27: 3 | K27: 3067 | L27: 4 | M27: 3.25 | N27: 0.012449596 | O27: DISTINCT, OPTIONAL
G28: C9 | H28: Hybrid | I28: 9 | J28: 3 | K28: 100 | L28: 4 | M28: 2.75 | N28: 0.01107262 | O28: OPTIONAL, ORDER BY, LIMIT
G29: C10 | H29: Hybrid | I29: 10 | J29: 3 | K29: 102 | L29: 5 | M29: 2.8 | N29: 0.002712048 | O29: DISTINCT
G30: Avg. | I30: =AVERAGE(I20:I29) -> 9.2 | J30: =AVERAGE(J20:J29) -> 4.2 | K30: =AVERAGE(K20:K29) -> 509.2 | L30: =AVERAGE(L20:L29) -> 4.3 | M30: =AVERAGE(M20:M29) -> 2.933 | N30: =AVERAGE(N20:N29) -> 0.013580744 | O30: -
G31: L1 | H31: Path | I31: 6 | J31: 3 | K31: 227192 | L31: 4 | M31: 2 | N31: 0.19222037 | O31: UNION
G32: L2 | H32: Hybrid | I32: 6 | J32: 3 | K32: 152899 | L32: 2 | M32: 3.5 | N32: 0.28678674 | O32: DISTINCT, FILTER
G33: L3 | H33: Hybrid | I33: 7 | J33: 3 | K33: 257158 | L33: 3 | M33: 3 | N33: 0.24582271 | O33: FILTER, ORDER BY
G34: L4 | H34: Hybrid | I34: 8 | J34: 4 | K34: 397204 | L34: 4 | M34: 2.5 | N34: 0.30567551 | O34: UNION, FILTER, REGEX
G35: L5 | H35: Hybrid | I35: 11 | J35: 4 | K35: 190575 | L35: 5 | M35: 3 | N35: 0.4858823 | O35: FILTER
G36: L6 | H36: Hybrid | I36: 10 | J36: 4 | K36: 282154 | L36: 5 | M36: 2.8 | N36: 0.34952898 | O36: FILTER, DISTINCT
G37: L7 | H37: Hybrid | I37: 5 | J37: 4 | K37: 80460 | L37: 3 | M37: 2.33 | N37: 0.20069629 | O37: DISTINCT, FILTER
G38: L8 | H38: Hybrid | I38: 8 | J38: 3 | K38: 306705 | L38: 4 | M38: 2.5 | N38: 0.27809356 | O38: UNION, FILTER
G39: Avg. | H39: - | I39: =AVERAGE(I31:I38) -> 7.625 | J39: =AVERAGE(J31:J38) -> 3.5 | K39: =AVERAGE(K31:K38) -> 236793.38 | L39: =AVERAGE(L31:L38) -> 3.75 | M39: =AVERAGE(M31:M38) -> 2.70375 | N39: =AVERAGE(N31:N38) -> 0.29308831 | O39: -

Sheet Spearman's corelation
D2: * Results are significant at 1% level, ** Results are significant at 5% level, ***Results are significant at 10% level
E4: FedX(Warm) | F4: SPLENDID | G4: ANAPSID | H4: FedX+HiBISCuS | I4: SPLENDID+HiBISCuS
D5: #TP | E5: 0.654347826086957* | F5: 0.536561264822134* | G5: 0.452608695652174** | H5: 0.620553359683794* | I5: 0.492094861660079*
D6: #Sources Span | E6: 0.23326087 | F6: 0.23221344 | G6: 0.24456522 | H6: 0.019268775 | I6: 0.29001976284585***
D7: #Results | E7: 0.582608695652174* | F7: 0.553112648221344* | G7: 0.084782609 | H7: 0.534090909090909* | I7: 0.47554347826087**
D8: #Join Vertices | E8: 0.275*** | F8: 0.288661067193676*** | G8: 0.21434783 | H8: 0.301259881422925*** | I8: 0.283720355731225***
D9: Mean Join Vertex Degree | E9: 0.499505928853755* | F9: 0.21005082 | G9: 0.22554348 | H9: 0.381705251270469** | I9: 0.18294749
D10: Mean TP Selectivity | E10: 0.26108696 | F10: 0.304347826086957*** | G10: 0.19804348 | H10: 0.23715415 | I10: 0.26284585
D11: Mean BGP-restricted TP Sel | E11: -0.064935065 | F11: -0.02173913 | G11: -0.19028797 | H11: -0.014116318 | I11: -0.04173913
D12: Mean Join-restricted TP Sel | E12: -0.508893280632411* | F12: -0.334115612648221*** | G12: -0.22374365 | H12: -0.472755505364201** | I12: -0.441847826086956**
K19: Query | L19: Structure | M19: #Triple Patterns | N19: #Sources Span | O19: #Results | P19: #Join Vertices | Q19: Mean Join Vertex Degree | R19: Mean Triple Pattern Selectivity | S19: Used SPARQL Clauses
K20: S1 | L20: Star | M20: 3 | N20: 2 | O20: 90 | P20: 1 | Q20: 2 | R20: 0.33333493 | S20: UNION
K21: S2 | L21: Star | M21: 3 | N21: 2 | O21: 1 | P21: 2 | Q21: 2 | R21: 0.007391659 | S21: X
K22: S3 | L22: Hybrid | M22: 5 | N22: 5 | O22: 2 | P22: 2 | Q22: 3 | R22: 0.008889571 | S22: X
K23: S4 | L23: Path | M23: 5 | N23: 5 | O23: 1 | P23: 5 | Q23: 2 | R23: 0.019295158 | S23: X
K24: S5 | L24: Path | M24: 4 | N24: 5 | O24: 2 | P24: 3 | Q24: 2 | R24: 0.006169376 | S24: X
K25: S6 | L25: Path | M25: 4 | N25: 4 | O25: 11 | P25: 3 | Q25: 2 | R25: 0.019395937 | S25: X
K26: S7 | L26: Path | M26: 4 | N26: 5 | O26: 1 | P26: 3 | Q26: 2 | R26: 0.020198747 | S26: X
K27: S8 | L27: - | M27: 2 | N27: 2 | O27: 1159 | P27: 0 | Q27: NA | R27: 0.00112084 | S27: UNION
K28: S9 | L28: Path | M28: 3 | N28: 4 | O28: 333 | P28: 1 | Q28: 2 | R28: 0.3335448 | S28: UNION
K29: S10 | L29: Hybrid | M29: 5 | N29: 2 | O29: 9054 | P29: 3 | Q29: 2.33 | R29: 0.016010968 | S29: X
K30: S11 | L30: Hybrid | M30: 7 | N30: 2 | O30: 3 | P30: 4 | Q30: 2.5 | R30: 0.006628492 | S30: X
K31: S12 | L31: Hybrid | M31: 6 | N31: 3 | O31: 393 | P31: 4 | Q31: 2.25 | R31: 0.01217423 | S31: X
K32: S13 | L32: Hybrid | M32: 5 | N32: 3 | O32: 28 | P32: 3 | Q32: 2.33 | R32: 0.014815076 | S32: X
K33: S14 | L33: Hybrid | M33: 5 | N33: 3 | O33: 1620 | P33: 3 | Q33: 2 | R33: 0.012452045 | S33: OPTIONAL
K34: C1 | L34: Hybrid | M34: 8 | N34: 5 | O34: 1000 | P34: 4 | Q34: 2.5 | R34: 0.010779222 | S34: DISTINCT, FILTER, OPTIONAL, LIMIT
K35: C2 | L35: Hybrid | M35: 8 | N35: 5 | O35: 4 | P35: 4 | Q35: 2.25 | R35: 0.00972466 | S35: OPTIONAL, FILTER
K36: C3 | L36: Hybrid | M36: 8 | N36: 3 | O36: 9 | P36: 4 | Q36: 2.25 | R36: 0.020214493 | S36: DISTINCT, OPTIONAL
K37: C5 | L37: Hybrid | M37: 8 | N37: 8 | O37: 500 | P37: 5 | Q37: 2.4 | R37: 0.018655228 | S37: FILTER, LIMIT
K38: C6 | L38: Hybrid | M38: 9 | N38: 2 | O38: 148 | P38: 5 | Q38: 2.8 | R38: 0.022971132 | S38: ORDER BY
K39: C7 | L39: Hybrid | M39: 9 | N39: 2 | O39: 112 | P39: 6 | Q39: 2.33 | R39: 0.014815749 | S39: DISTINCT, OPTIONAL
... K42: L7 | L42: Hybrid | M42: 5 | N42: 4 | O42: 80460 | P42: 3 | Q42: 2.33 | R42: 0.20069629 | S42: DISTINCT, FILTER

Sheet Number of Endpoints Requests
B3: Query | C3: FedX | D3: SPLENDID | E3: ANAPSID | F3: FedX+HiBISCuS | G3: SPLENDID+HiBISCuS
B4: S1 | C4: 15 | D4: 46 | E4: 25 | F4: 4 | G4: 4 | I4: =C4-F4 -> 11
B5: S2 | C5: 2 | D5: 12 | E5: 3 | F5: 2 | G5: 2
B6: S3 | C6: 34 | D6: 23 | E6: 4 | F6: 10 | G6: 11
B7: S4 | C7: 59 | D7: 15 | E7: 5 | F7: 3 | G7: 3
B8: S5 | C8: 27 | D8: 18 | E8: 3 | F8: 6 | G8: 7
B9: S6 | C9: 276 | D9: 3694 | E9: 19 | F9: 186 | G9: 2458
B10: S7 | C10: 341 | D10: 495 | E10: 759 | F10: 2881 | G10: 482
B11: S8 | C11: 1 | D11: 2 | E11: 1 | F11: 1 | G11: 1
B12: S9 | C12: 53 | D12: 142 | E12: 38 | F12: 29 | G12: 65 | L12: 13857
B13: S10 | C13: 3527 | D13: 4361 | E13: 452 | F13: 4335 | G13: 71020 | L13: 5416
B14: S11 | C14: 3 | D14: 10 | E14: 6 | F14: 2 | G14: 3 | L14: 61
B15: S12 | C15: 639 | D15: 7442 | E15: 400 | F15: 458 | G15: 6539 | L15: 6
B16: S13 | C16: 50909 | D16: 380 | E16: 21 | F16: 50896 | G16: 315 | L16: 110
B17: S14 | C17: 1961 | D17: 6509 | E17: 233 | F17: 1960 | G17: 6503 | L17: =SUM(L12:L16) -> 19450
B18: Total | C18: 57847 | D18: 23149 | E18: 1969 | F18: 60773 | G18: 87413
B19: C1 | C19: 1991 | D19: 5235 | E19: 26 | F19: 1191 | G19: 3147 | M19: 1000
B20: C2 | C20: 549 | D20: 6649 | E20: 266 (ZRE) | F20: 549 | G20: 5222 | M20: 4
B21: C3 | C21: 6697 | D21: 13854 | E21: 1350 (ZRT) | F21: 6697 | G21: 3299 | M21: 9
B22: C4 | C22: 120892 | D22: 78 (ZRE) | E22: 454 | F22: 370 | G22: 0 (ZRE) | M22: 50
B23: C5 | C23: 19450 (ZRT) | D23: 311578 (2.2%) | E23: 0 (ZRE) | F23: 3568 (ZRT) | G23: 500 | J23: =11/500*100 -> 2.2 | M23: 500
B24: C6 | C24: 12386 | D24: 20 | E24: 274 | F24: 15738 | G24: 2 | M24: 148
B25: C7 | C25: 572 | D25: 761 | E25: 67 | F25: 78 | G25: 78 | M25: 112
B26: C8 | C26: 1290 | D26: 5871 | E26: 108 | F26: 613 | G26: 609 | M26: 3067
B27: C9 | C27: 2487 (ZRT) | D27: 5392 (ZRE) | E27: 581 | F27: 183 (ZRT) | G27: 37211 (ZRE) | M27: 100
B28: C10 | C28: 953 | D28: 984 | E28: 278 | F28: 892 | G28: 901 | M28: 102
B29: Total | C29: 167267 | D29: 350422 | E29: 3404 | F29: 29879 | G29: 50969
B30: L1 | C30: 2320 (7.2 %) | D30: 16 (2.73 %) | E30: 1947 (15.76 %) | F30: 2320 (7.2 %) | G30: 16 (2.73 %) | J30: 6206 | K30: =J30/M30*100 -> 2.7316103 | M30: 227192
B31: L2 | C31: 1 (0 %) | D31: 80 (1.8 %) | E31: 1609 (ZRT) | F31: 1 (0 %) | G31: 80 (1.80 %) | J31: 2760 | K31: =J31/M31*100 -> 1.8051132 | M31: 152899
B32: L3 | C32: 1 (0 %) | D32: 2734572 | E32: 5553 (ZRT) | F32: 1 (0 %) | G32: 2734572 | J32: 0 | K32: =J32/M32*100 -> 0 | M32: 257158
B33: L4 | C33: 3967 (0.08 %) | D33: 16321 (0 %) | E33: 11290 (0 %) | F33: 15721 (48.34 %) | G33: 16220 (0 %) | J33: 192032 | K33: =J33/M33*100 -> 48.345938 | M33: 397204
B34: L5 | C34: 1 (0 %) | D34: 28342 (ZRE) | E34: 3840 (ZRT) | F34: 1 (0 %) | G34: 28212 (ZRE) | J34: 0 | K34: =J34/M34*100 -> 0 | M34: 190575
B35: L6 | C35: 3830809 (ZRT) | D35: 61810 (ZRE) | E35: 1707 (ZRT) | F35: 3414400 (0 %) | G35: 61419 (ZRE) | J35: 0 | K35: =J35/M35*100 -> 0 | M35: 282154
B36: L7 | C36: 74387 | D36: 867628 | E36: 267 | F36: 23381 | G36: 1341384 | J36: 80459 | K36: =J36/M36*100 -> 100 | M36: 80459
B37: L8 | C37: 206859 (0.01 %) | D37: 2423783 (0.05 %) | E37: 17302 (0.05 %) | F37: 206859 (0.01 %) | G37: 2423783 (0.05 %) | J37: 156 | K37: =J37/M37*100 -> 0.050863207 | M37: 306705
B38: Total | C38: 4118345 | D38: 6132552 | E38: 43515 | F38: 3662684 | G38: 6605686
B39: Net Total | C39: 4343459 | D39: 6506123 | E39: 48888 | F39: 3753336 | G39: 6744068
B42: Query | C42: FedX(cold) | D42: FedX(100% cached) | E42: SPLENDID | F42: ANAPSID | G42: FedX+HiBISCuS | H42: SPLENDID+HiBISCuS
B43: B1 | C43: 16347 (2320) | D43: 16347 (2320) | E43: 6206(16) 123735 | F43: 35810(1947)19672 | G43: 16347 (2320) | H43: 6206(16) 123735
B44: B2 | C44: 0 (1) | D44: 0 (1) | E44: 2760,80 , 45473 | F44: 0,1609,TO | G44: 0 (1) | H44: 2760,80 , 45473
...
